<?xml version='1.0' encoding='utf-8'?>
<robot name="atlasr1" xmlns:xacro="http://ros.org/wiki/xacro">

<!-- Start GZ or Ignition depending on ROS 2 Version -->
<xacro:arg name="is_ignition" default="true"/>

<!-- Include Gazebo Parameters -->
<xacro:include filename="$(find atlasr1_description)/urdf/atlasr1_gazebo.xacro" />




<link name= "base_footprint"/>
    <link name="base_link">
        <inertial>
            <origin xyz="3.60308280294404e-05 2.4467600546033853e-05 -0.02676504245712244" rpy="0.0 0.0 0.0" />
            <mass value="2.0846238689374457" />
            <inertia ixx="0.007645409817463705" iyy="0.007636442610918238" izz="0.013171282242772312" ixy="4.752449753004864e-06" iyz="5.714577867747551e-07" ixz="6.864134449094882e-07" />
        </inertial>
        <visual name="base_link_visual">
            <origin xyz="0.0 0.0 0.0" rpy="0.0 0.0 0.0" />
            <geometry>
                <mesh filename="package://atlasr1_description/meshes/base_link.stl" scale="0.001 0.001 0.001" />
            </geometry>
        </visual>
        <collision name="base_link_collision">
            <origin xyz="0.0 0.0 0.0" rpy="0.0 0.0 0.0" />
            <geometry>
                <mesh filename="package://atlasr1_description/meshes/base_link.stl" scale="0.001 0.001 0.001" />
            </geometry>
        </collision>
    </link>
    <link name="wheel_1">
        <inertial>
            <origin xyz="-0.009526274321752926 6.716849298982197e-17 0.005499998432966722" rpy="0.0 -5.551115123125784e-17 -5.473822126268818e-48" />
            <mass value="0.1848405762145018" />
            <inertia ixx="3.031783270083665e-05" iyy="2.330841340246275e-05" izz="2.5644886524263573e-05" ixy="-5.1875310187790015e-21" iyz="-1.4731855232755645e-20" ixz="-4.046890099429457e-06" />
        </inertial>
        <visual name="wheel_1_visual">
            <origin xyz="-0.00952627432172484 6.411537967210279e-17 0.005499998433015376" rpy="-6.883183981608445e-16 -1.047197551196599 1.5556928265181944e-17" />
            <geometry>
                <mesh filename="package://atlasr1_description/meshes/wheel_1.stl" scale="0.001 0.001 0.001" />
            </geometry>
        </visual>
        <collision name="wheel_1_collision">
            <origin xyz="-0.00952627432172484 6.411537967210279e-17 0.005499998433015376" rpy="-6.883183981608445e-16 -1.047197551196599 1.5556928265181944e-17" />
            <geometry>
                <mesh filename="package://atlasr1_description/meshes/wheel_1.stl" scale="0.001 0.001 0.001" />
            </geometry>
        </collision>
    </link>
    <link name="lidar">
        <inertial>
            <origin xyz="-0.0028401587113255793 0.011516910445471871 -0.012673516286964545" rpy="0.0 -0.0 0.0" />
            <mass value="0.30908631325941793" />
            <inertia ixx="0.0003697647066074499" iyy="0.0001397540557933571" izz="0.00043841551665642836" ixy="6.0103796521837945e-05" iyz="-2.282328868113959e-05" ixz="5.1830694601318e-06" />
        </inertial>
        <visual name="lidar_visual">
            <origin xyz="3.7148159075630142e-09 -0.0010499981747626491 9.999999999994457e-05" rpy="-3.1415926535897922 -5.672345478157063e-17 -1.5707963267949006" />
            <geometry>
                <mesh filename="package://atlasr1_description/meshes/lidar.stl" scale="0.001 0.001 0.001" />
            </geometry>
        </visual>
        <collision name="lidar_collision">
            <origin xyz="3.7148159075630142e-09 -0.0010499981747626491 9.999999999994457e-05" rpy="-3.1415926535897922 -5.672345478157063e-17 -1.5707963267949006" />
            <geometry>
                <mesh filename="package://atlasr1_description/meshes/lidar.stl" scale="0.001 0.001 0.001" />
            </geometry>
        </collision>
    </link>
    <link name="wheel_2">
        <inertial>
            <origin xyz="5.643759648132495e-14 1.7208456881689926e-17 -0.010999998174762817" rpy="0.0 -0.0 0.0" />
            <mass value="0.1848405762145018" />
            <inertia ixx="2.330841343597674e-05" iyy="2.3308413402462532e-05" izz="3.2654305789123016e-05" ixy="1.456355975014767e-20" iyz="1.0164395367051604e-20" ixz="-2.2575400807878472e-20" />
        </inertial>
        <visual name="wheel_2_visual">
            <origin xyz="2.708944180085382e-16 1.4155343563970746e-17 -0.010999998174762817" rpy="3.141592653589793 1.609823385706477e-15 -3.1415926535897927" />
            <geometry>
                <mesh filename="package://atlasr1_description/meshes/wheel_2.stl" scale="0.001 0.001 0.001" />
            </geometry>
        </visual>
        <collision name="wheel_2_collision">
            <origin xyz="2.708944180085382e-16 1.4155343563970746e-17 -0.010999998174762817" rpy="3.141592653589793 1.609823385706477e-15 -3.1415926535897927" />
            <geometry>
                <mesh filename="package://atlasr1_description/meshes/wheel_2.stl" scale="0.001 0.001 0.001" />
            </geometry>
        </collision>
    </link>
    <link name="wheel_3">
        <inertial>
            <origin xyz="0.009526274321696953 -2.1649348980190553e-17 0.005499998433064182" rpy="0.0 -4.103888240278703e-80 0.0" />
            <mass value="0.1848405762145018" />
            <inertia ixx="3.0317832700836518e-05" iyy="2.3308413402462966e-05" izz="2.56448865242636e-05" ixy="-1.6365106897801174e-20" iyz="5.536121271884489e-21" ixz="4.046890099429601e-06" />
        </inertial>
        <visual name="wheel_3_visual">
            <origin xyz="0.009526274321725037 -2.4702462297909733e-17 0.005499998433015545" rpy="5.583374838072268e-16 1.0471975511965959 1.607181668509713e-16" />
            <geometry>
                <mesh filename="package://atlasr1_description/meshes/wheel_3.stl" scale="0.001 0.001 0.001" />
            </geometry>
        </visual>
        <collision name="wheel_3_collision">
            <origin xyz="0.009526274321725037 -2.4702462297909733e-17 0.005499998433015545" rpy="5.583374838072268e-16 1.0471975511965959 1.607181668509713e-16" />
            <geometry>
                <mesh filename="package://atlasr1_description/meshes/wheel_3.stl" scale="0.001 0.001 0.001" />
            </geometry>
        </collision>
    </link>

    <joint name="base_joint" type="fixed">
        <parent link="base_footprint"/>
        <child link="base_link" />
        <origin xyz="0 0 0.033" rpy="3.141592653589793 0 0"/>
    </joint>
   <joint name="lidar_joint" type="fixed">
        <origin xyz="-3.257000000001405e-05 -1.8252373001903522e-09 -0.07599999999999991" rpy="4.190444008670316e-17 3.3306690738754726e-16 -8.01265631529022e-48" />
        <parent link="base_link" />
        <child link="lidar" />
    </joint>
    <joint name="wheel_1_joint" type="continuous">
        <origin xyz="0.06706144000000014 -0.03871794182523728 0.0014999999999999783" rpy="1.5707963267948968 -2.0282376334022125e-16 2.0943951023931984" />
        <parent link="base_link" />
        <child link="wheel_1" />
        <axis xyz="-0.8660252018922192 -1.3684555315672042e-48 0.4999996503124188" />
    </joint>
    <joint name="wheel_2_joint" type="continuous">
        <origin xyz="-3.1036880516480075e-16 0.07743587817476268 0.0015000000000000055" rpy="1.5707963267948966 3.3306690738754726e-16 -8.01265631529022e-48" />
        <parent link="base_link" />
        <child link="wheel_2" />
        <axis xyz="0.0 2.7369110631344083e-48 -1.0" />
    </joint>
    <joint name="wheel_3_joint" type="continuous">
        <origin xyz="-0.0670614399999999 -0.03871794182523728 0.001500000000000023" rpy="1.5707963267948963 -1.3024314404732606e-16 -2.094395102393193" />
        <parent link="base_link" />
        <child link="wheel_3" />
        <axis xyz="0.8660252018922194 -1.3684555315672042e-48 0.4999996503124185" />
    </joint>
</robot>